name: Python API > Pagefind error handling
platforms:
  - linux
  - mac

steps:
  - ref: ./background.toolproof.yml
  - step: I have a "public/run.py" file with the content {python}
    python: |2-
      import sys
      sys.path.append('%toolproof_process_directory%/wrappers/python/src')

      import asyncio
      import json
      import logging
      import os
      from pagefind.index import PagefindIndex, IndexConfig

      async def main():
        async with PagefindIndex() as index:
          await index.delete_index()
          try:
            files = await index.get_files()
          except AssertionError:
            print("Index deleted")

        try:
          async with PagefindIndex(IndexConfig(root_selector=5)) as index:
            await index.delete_index()
        except Exception as e:
          print(f"Caught error {e}")

        print("Complete")
      if __name__ == "__main__":
        asyncio.run(main())
  - macro: I run Pagefind Python as "run.py" in "public"
  - step: 'stdout should contain "invalid type: integer `5`"'
  - step: stdout should contain "Index deleted"
